[2021-12-14 02:24:06,131]	INFO	[log_main.py:<module>:23]	>> 1/3 = 0.3333333333333333
[2021-12-14 02:24:06,137]	INFO	[log_main.py:<module>:23]	>> 1/2 = 0.5
[2021-12-14 02:24:06,139]	INFO	[log_main.py:<module>:23]	>> 1/1 = 1.0
[2021-12-14 02:24:06,141]	ERROR	[log_main.py:handle_exception:10]	>> Unexpected exception
Traceback (most recent call last):
  File "/Users/thkim/Coding/raffle/test/log_main.py", line 20, in <module>
    num = 1/i
ZeroDivisionError: division by zero

During handling of the above exception, another exception occurred:

Traceback (most recent call last):
  File "/Users/thkim/Coding/raffle/test/log_main.py", line 22, in <module>
    raise ZeroDivisionError()
ZeroDivisionError
